{
  "cveId": "CVE-2025-2953",
  "eventName": "CVE Modified",
  "cveChangeId": "1D62BD2A-A798-4254-8CE0-61CB124A7D54",
  "sourceIdentifier": "cna@vuldb.com",
  "created": "2025-04-22T12:15:16.043",
  "details": [
    {
      "action": "Added",
      "type": "Tag",
      "newValue": "disputed"
    },
    {
      "action": "Changed",
      "type": "Description",
      "oldValue": "A vulnerability, which was classified as problematic, has been found in PyTorch 2.6.0+cu124. Affected by this issue is the function torch.mkldnn_max_pool2d. The manipulation leads to denial of service. An attack has to be approached locally. The exploit has been disclosed to the public and may be used.",
      "newValue": "A vulnerability, which was classified as problematic, has been found in PyTorch 2.6.0+cu124. Affected by this issue is the function torch.mkldnn_max_pool2d. The manipulation leads to denial of service. An attack has to be approached locally. The exploit has been disclosed to the public and may be used. The real existence of this vulnerability is still doubted at the moment. The security policy of the project warns to use unknown models which might establish malicious effects."
    },
    {
      "action": "Added",
      "type": "Reference",
      "newValue": "https://github.com/pytorch/pytorch/blob/main/SECURITY.md#untrusted-models"
    }
  ]
}